#  Copied code from http://stackoverflow.com/questions/6728236/exception-thrown-in-multiprocessing-pool-not-detected
import traceback
from multiprocessing.pool import Pool
import multiprocessing
import logging
import sys


LOGGER = multiprocessing.get_logger()
LOGGER.setLevel(logging.WARN)
console_handler = logging.StreamHandler(sys.stdout)
formatter = logging.Formatter('%(asctime)s - [%(levelname)s] [%(name)s] [%(process)d] %(message)s')
console_handler.setFormatter(formatter)
LOGGER.addHandler(console_handler)

# Shortcut to multiprocessing's logger
def error(msg, *args):
    return multiprocessing.get_logger().error(msg, *args)

class LogExceptions(object):
    def __init__(self, callable):
        self.__callable = callable
        return

    def __call__(self, *args, **kwargs):
        try:
            result = self.__callable(*args, **kwargs)

        except Exception as e:
            # Here we add some debugging help. If multiprocessing's
            # debugging is on, it will arrange to log the traceback
            error(traceback.format_exc())
            # Re-raise the original exception so the Pool worker can
            # clean up
            raise Exception

        # It was fine, give a normal answer
        return result
    pass


class LoggingPool(Pool):
    def apply_async(self, func, args=(), kwds={}, callback=None):
        return Pool.apply_async(self, LogExceptions(func), args, kwds, callback)